Workbook
Name Amort_Bat: Hypotheses!$F$33
Name Amort_Equipement: Hypotheses!$F$35
Name Amort_Installation: Hypotheses!$F$37
Name Amort_MMB: Hypotheses!$F$34
Name Amort_Vehicule: Hypotheses!$F$36
Name ChoixVerC: #REF!
Name Cot_sociales: #REF!
Name CountryList: #REF!
Name Cout_Projet: #REF!
Name CurrToggle: #REF!
Name DaysPayable: Cashflow!$F$17
Name DaysReceivable: Cashflow!$F$16
Name Delais_clients: Hypotheses!$F$28
Name Delais_Frs: Hypotheses!$F$29
Name Delais_Stocks: Hypotheses!$F$30
Name Inflation: Hypotheses!$F$24
Name InventoryTurnover: Cashflow!$F$18
Name jours_an: Hypotheses!$F$25
Name Prix1: #REF!
Name Prix2: #REF!
Name Prix3: #REF!
Name Taux_interet: Hypotheses!$F$23
Name Taux_IS: Hypotheses!$F$22
Name Volume1: #REF!
Name Volume2: #REF!
Name Volume3: #REF!

Sheet Landing Page
C2: LANDING PAGE
C5: Données générales | H5: Contacts
C7: Nom de la structure | E7: DEMARCH | I7: Dirigeant
C9: Secteur d'activités | I9: Téléphone
C11: Chiffres d'affaires estimé | I11: Email
C13: Montant souhaité | I13: Préférence d'appel
C15: Montant précis | I15: Urgence
C17: Nature du besoin | I17: Source d'informations
C19: Anciennété
C21: Employés
C23: Ville / Zone

Sheet Sommaire
C2: Sommaire
C7: Présentation de l'entreprise
C10: Données générales
C12: Nom de la structure
C14: Année de création
C16: Forme juridique
C18: Activité principale
C20: Adresse
C22: Ville
C24: Point focal
C26: Fonction
C28: Tel
... C34: Dernier exercice clôturé
C36: États financiers certifiés | E36: Etats financiers fiannciers
C38: Cabinet d'assistance comptable | E38: OUI
C40: Commissaire aux comptes | E40: Néant
C43: Actionnariat
D45: Prénom | E45: Nom | F45: % détenu
C47: 1-
C55: 2-
C57: 3-
C59: 3-
C65: Total | F65: =F47+F55+F57+F59 -> 0 | G65: =IF(F65<>1,"Le total doit être égal à 100%. Vérifiez les données!","") -> Le total doit être égal à 100%. Vérifiez les données!
C67: Management et Oragnigramme
D69: Prénom | E69: Nom | F69: Fonction/ Année d'expérience
C71: 1-
C73: 2-
C75: 3-
C77: 4-
C79: 5-
C81: 7-
C83: 8-
C90: Historique de l'entreprise
C103: Relations bancaires
D105: Banque | E105: Engagement en cours | F105: N° Compte
C107: 1- | D107: Ecobank | E107: Aucun
C109: 2-
C111: 3-
C113: 4-
C115: Coordonnées Agence
...

Sheet Checklist
C2: Liste indicative des documents à fournir
C8: Quincaillerie
C11: 1 | D11: Ninea | E11: Non
C12: 2 | D12: RCCM | E12: Non
C13: 3 | D13: Copie CNI | E13: Non
C14: 4 | D14: États financiers 2023 | E14: Non
C15: 5 | D15: États financiers 2024 | E15: Non
C16: 6 | D16: États financiers 2025 | E16: Non
C17: 7 | D17: Relevé bancaire (banque principale) | E17: Non
C18: 8 | D18: Relevé bancaire (banque secondaire) | E18: Non
C19: 9 | D19: Factures pro forma à jour (Investissements) | E19: Non
C20: 10 | D20: Factures pro forma à jour (Exploitation) | E20: Non
C21: 11 | D21: Courrier demande de financement | E21: Non
C22: 12 | D22: Contrat d'engagement Kapit signé | E22: Non
C23: 13
C24: 14
C25: 15
C26: 16
C27: 17
C28: 18
C29: 19
C30: 20
C31: 21
C32: 22
C33: 23
C34: 24
C35: 25

Sheet Hypotheses
D2: HYPOTHÈSES GENERALES | H2: Cellules à renseigner
H3: Cellules contenant des formules / Résultats générés automatiquement
D5: Sommaire | E5: unité | F5: Baseline | G5: 2025 | H5: =G5+1 -> 2026 | I5: =H5+1 -> 2027 | J5: =I5+1 -> 2028 | K5: =J5+1 -> 2029
D8: A. Paramètres
D9: Insérer noms des produit/services et modifier les autres cellules si opportun
D11: Région | E11: Dakar
D13: Devise | E13: XOF
D15: Offre de Produits/Services | I15: Matière 1ère
D16: Produit/Service 1 | E16: Produit 1 | I16: Matière 1ère A | J16: Matière A
D17: Produit/Service 2 | E17: Produit 2 | I17: Matière 1ère A | J17: Matière B
D18: Produit/Service 3 | E18: Produit 3 | I18: Matière 1ère A | J18: Matière C
D19: Produit/Service 4 | E19: Produit 4 | I19: Matière 1ère A | J19: Matière D
D20: Produit/Service 5 | E20: Produit 5 | I20: Matière 1ère A | J20: Matière E
D22: Taux Impôt sur les sociétés | E22: % | F22: 0.3 | G22: =IF(Taux_IS="","Required field","")
D23: Taux d'intérêt emprunts | E23: % | F23: 9
D24: Taux d'inflation | E24: % | F24: 0.0112 | G24: =IF(Inflation="","Required field","")
D25: Jours par an | E25: jours | F25: 365
D26: Nombre de mensualité | E26: mois | F26: 12
D27: Nb semaines par an | E27: semaines | F27: 52
D28: Délais de paiement des clients | E28: jours | F28: 30
D29: Délais fournisseurs | E29: jours | F29: 30
D30: Délais de rotation des stocks | E30: jours | F30: 60
D32: Taux Amortissements Immo
D33: Terrains | E33: An | F33: 0
D34: Batiments & travaux publics | E34: An | F34: 10
D35: Aménagement, agencement et Installation | E35: An | F35: 10
D36: Matériel d'exploitation | E36: An | F36: 10
D37: Véhicule | E37: An | F37: 5
D38: Matériel et outillage | E38: An | F38: 5
D39: Matériel et Mobilier de bureau | E39: An | F39: 5
D40: Stress test | E40: % | F40: 0.85
D43: B. Hypothèses d'exploitation
D44: Mettre les volumes constatés durant l'année de référence
D46: Recettes | I46: Charges | J46: Qté/Unité/mois | K46: Prix (FCFA) | L46: Total Mensuel (FCFA)
D47: =IF(E16="","Produit/Service 1",E16) -> Produit 1 | I47: =D87 -> Achat de matière et fourniture liée | J47: =SUM(J48:J52) -> 125 | K47: =SUM(K48:K52) -> 1290 | L47: =SUM(L48:L52) -> 28300
D48: Quantité/Jour | E48: Nbre | G48: 6 | I48: =D88 -> Matière A | J48: 10 | K48: 300 | L48: =J48*K48 -> 3000
D49: Prix | E49: FCFA | G49: 10000 | I49: =D89 -> Matière B | J49: 70 | K49: 210 | L49: =J49*K49 -> 14700
D50: =IF(E17="","Produit/Service 2",E17) -> Produit 2 | I50: =D90 -> Matière C | J50: 20 | K50: 230 | L50: =J50*K50 -> 4600
D51: Quantité vendue/Jour | E51: Nbre | G51: 5 | I51: =D91 -> Matière D | J51: 16 | K51: 150 | L51: =J51*K51 -> 2400
D52: Prix | E52: FCFA | G52: 15000 | I52: =D92 -> Matière E | J52: 9 | K52: 400 | L52: =J52*K52 -> 3600
...

Sheet Estimation des autres charges
A3: Consommation d'électricité | E3: Charges salariales
A6: Année | B6: =+Hypotheses!G5 -> 2025 | E6: Nom employé | F6: Revenu Brut Mensuel | G6: Devise | H6: Revenu Brut Annuel
A7: Janvier | B7: 0 | C7: XOF | E7: A | F7: 2000000 | G7: XOF | H7: =F7*Hypotheses!F26 -> 24000000
A8: février | B8: 0 | C8: XOF | E8: B | F8: 0 | G8: XOF | H8: =F8*Hypotheses!F27 -> 0
A9: mars | B9: 0 | C9: XOF | E9: C | F9: 0 | G9: XOF | H9: =F9*Hypotheses!F28 -> 0
A10: avril | B10: 0 | C10: XOF | E10: D | F10: 0 | G10: XOF | H10: =F10*Hypotheses!F29 -> 0
A11: mai | B11: 0 | C11: XOF | E11: E | F11: 0 | G11: XOF | H11: =F11*Hypotheses!F30 -> 0
A12: juin | B12: 0 | C12: XOF | E12: F | F12: 0 | G12: XOF | H12: =F12*Hypotheses!F31 -> 0
A13: juillet | B13: 0 | C13: XOF | E13: G | F13: 0 | G13: XOF | H13: =F13*Hypotheses!F32 -> 0
A14: août | B14: 0 | C14: XOF | E14: H | F14: 0 | G14: XOF | H14: =F14*Hypotheses!F33 -> 0
A15: septembre | B15: 0 | C15: XOF | E15: I | F15: 0 | G15: XOF | H15: =F15*Hypotheses!F34 -> 0
A16: octobre | B16: 0 | C16: XOF | E16: J | F16: 0 | G16: XOF | H16: =F16*Hypotheses!F35 -> 0
A17: novembre | B17: 0 | C17: XOF | E17: K | F17: 0 | G17: XOF | H17: =F17*Hypotheses!F36 -> 0
A18: décembre | B18: 0 | C18: XOF | E18: L | F18: 0 | G18: XOF | H18: =F18*Hypotheses!F37 -> 0
B19: =AVERAGE(B7:B18) -> 0 | C19: XOF | H19: =SUM(H7:H18) -> 24000000
A24: Consommation d'eau
A27: Année | B27: =+Hypotheses!G5 -> 2025
A28: Janvier | B28: 0 | C28: XOF
A29: février | B29: 0 | C29: XOF
A30: mars | B30: 0 | C30: XOF
A31: avril | B31: 0 | C31: XOF
A32: mai | B32: 0 | C32: XOF
A33: juin | B33: 0 | C33: XOF
A34: juillet | B34: 0 | C34: XOF
A35: août | B35: 0 | C35: XOF
A36: septembre | B36: 0 | C36: XOF
A37: octobre | B37: 0 | C37: XOF
A38: novembre | B38: 0 | C38: XOF
A39: décembre | B39: 0 | C39: XOF
B40: =AVERAGE(B28:B39) -> 0 | C40: XOF
A44: Consommation Téléphone
A47: Année | B47: =+Hypotheses!G5 -> 2025
A48: Janvier | B48: 0 | C48: XOF
A49: février | B49: 0 | C49: XOF
A50: mars | B50: 0 | C50: XOF
A51: avril | B51: 0 | C51: XOF
A52: mai | B52: 0 | C52: XOF
A53: juin | B53: 0 | C53: XOF
A54: juillet | B54: 0 | C54: XOF
A55: août | B55: 0 | C55: XOF
...

Sheet OPEX
C2: COMPTE D'EXPLOITATION PREVISIONNEL
F5: =Hypotheses!G5 -> 2025 | G5: =Hypotheses!H5 -> 2026 | H5: =Hypotheses!I5 -> 2027 | I5: =Hypotheses!J5 -> 2028 | J5: =Hypotheses!K5 -> 2029
G6: =+(G7-F7)/F7 -> 8.0766667 | H6: =+(H7-G7)/G7 -> 0.037330151 | I6: =+(I7-H7)/H7 -> 0.038017276 | J6: =+(J7-I7)/I7 -> 0.03876664
C7: Recettes | E7: tot. | F7: =+F9+F12+F15+F18+F21 -> 15 | G7: =+G9+G12+G15+G18+G21 -> 136.15 | H7: =+H9+H12+H15+H18+H21 -> 141.2325 | I7: =+I9+I12+I15+I18+I21 -> 146.60178 | J7: =+J9+J12+J15+J18+J21 -> 152.28503
D8: =+Hypotheses!D69 -> Produit 1 | E8: =Hypotheses!$E$13 -> XOF | F8: =F9*F10*Hypotheses!$F$25 -> 21900000 | G8: =G9*G10*Hypotheses!$F$25 -> 459900000 | H8: =H9*H10*Hypotheses!$F$25 -> 473697000 | I8: =I9*I10*Hypotheses!$F$25 -> 4.8790791e+08 | J8: =J9*J10*Hypotheses!$F$25 -> 5.0254515e+08
D9: =Hypotheses!D48 -> Quantité/Jour | F9: =+Hypotheses!G48 -> 6 | G9: =F9*(1+Hypotheses!H70) -> 126 | H9: =G9*(1+Hypotheses!I70) -> 129.78 | I9: =H9*(1+Hypotheses!J70) -> 133.6734 | J9: =I9*(1+Hypotheses!K70) -> 137.6836
D10: =Hypotheses!D49 -> Prix | F10: =+Hypotheses!G49 -> 10000 | G10: =F10*(1+Hypotheses!H71) -> 10000 | H10: =G10*(1+Hypotheses!I71) -> 10000 | I10: =H10*(1+Hypotheses!J71) -> 10000 | J10: =I10*(1+Hypotheses!K71) -> 10000
D11: =Hypotheses!D72 -> Produit 2 | E11: =Hypotheses!$E$13 -> XOF | F11: =F12*F13*Hypotheses!$F$25 -> 27375000 | G11: =G12*G13*Hypotheses!$F$25 -> 31481250 | H11: =H12*H13*Hypotheses!$F$25 -> 36203438 | I11: =I12*I13*Hypotheses!$F$25 -> 41633953 | J11: =J12*J13*Hypotheses!$F$25 -> 47879046
D12: =Hypotheses!D51 -> Quantité vendue/Jour | F12: =+Hypotheses!G51 -> 5 | G12: =(F12*(1+Hypotheses!H73)) -> 5.75 | H12: =(G12*(1+Hypotheses!I73)) -> 6.6125 | I12: =(H12*(1+Hypotheses!J73)) -> 7.604375 | J12: =(I12*(1+Hypotheses!K73)) -> 8.7450312
D13: =Hypotheses!D52 -> Prix | F13: =+Hypotheses!G52 -> 15000 | G13: =(F13*(1+Hypotheses!H74)) -> 15000 | H13: =(G13*(1+Hypotheses!I74)) -> 15000 | I13: =(H13*(1+Hypotheses!J74)) -> 15000 | J13: =(I13*(1+Hypotheses!K74)) -> 15000
D14: =+Hypotheses!D75 -> Produit 3 | E14: =Hypotheses!$E$13 -> XOF | F14: =F15*F16*Hypotheses!$F$25 -> 29200000 | G14: =G15*G16*Hypotheses!$F$25 -> 32120000 | H14: =H15*H16*Hypotheses!$F$25 -> 35332000 | I14: =I15*I16*Hypotheses!$F$25 -> 38865200 | J14: =J15*J16*Hypotheses!$F$25 -> 42751720
D15: =Hypotheses!D54 -> Quantité vendue/Jour | F15: =+Hypotheses!G54 -> 4 | G15: =(F15*(1+Hypotheses!H76)) -> 4.4 | H15: =(G15*(1+Hypotheses!I76)) -> 4.84 | I15: =(H15*(1+Hypotheses!J76)) -> 5.324 | J15: =(I15*(1+Hypotheses!K76)) -> 5.8564
D16: =Hypotheses!D55 -> Prix | F16: =+Hypotheses!G55 -> 20000 | G16: =(F16*(1+Hypotheses!H77)) -> 20000 | H16: =(G16*(1+Hypotheses!I77)) -> 20000 | I16: =(H16*(1+Hypotheses!J77)) -> 20000 | J16: =(I16*(1+Hypotheses!K77)) -> 20000
D17: =+Hypotheses!D78 -> Produit 4 | E17: =Hypotheses!$E$13 -> XOF | F17: =F18*F19*Hypotheses!$F$25 -> 0 | G17: =(F17*(1+Hypotheses!H78)) -> 0 | H17: =H18*H19*Hypotheses!$F$25 -> 0 | I17: =I18*I19*Hypotheses!$F$25 -> 0 | J17: =J18*J19*Hypotheses!$F$25 -> 0
D18: =Hypotheses!D57 -> Quantité vendue/Jour | F18: =Hypotheses!G57 -> 0 | G18: =(F18*(1+Hypotheses!H79)) -> 0 | H18: =(G18*(1+Hypotheses!I79)) -> 0 | I18: =(H18*(1+Hypotheses!J79)) -> 0 | J18: =(I18*(1+Hypotheses!K79)) -> 0
D19: =Hypotheses!D58 -> Prix | F19: =Hypotheses!G58 -> 0 | G19: =(F19*(1+Hypotheses!H80)) -> 0 | H19: =(G19*(1+Hypotheses!I80)) -> 0 | I19: =(H19*(1+Hypotheses!J80)) -> 0 | J19: =(I19*(1+Hypotheses!K80)) -> 0
D20: =+Hypotheses!D81 -> Produit 5 | E20: =Hypotheses!$E$13 -> XOF | F20: =F21*F22*Hypotheses!$F$25 -> 0 | G20: =G21*G22*Hypotheses!$F$25 -> 0 | H20: =H21*H22*Hypotheses!$F$25 -> 0 | I20: =I21*I22*Hypotheses!$F$25 -> 0 | J20: =J21*J22*Hypotheses!$F$25 -> 0
D21: =Hypotheses!D60 -> Quantité vendue/Jour | F21: =Hypotheses!G60 -> 0 | G21: =(F21*(1+Hypotheses!H82)) -> 0 | H21: =(G21*(1+Hypotheses!I82)) -> 0 | I21: =(H21*(1+Hypotheses!J82)) -> 0 | J21: =(I21*(1+Hypotheses!K82)) -> 0
D22: =Hypotheses!D61 -> Prix | F22: =Hypotheses!G61 -> 0 | G22: =(F22*(1+Hypotheses!H83)) -> 0 | H22: =(G22*(1+Hypotheses!I83)) -> 0 | I22: =(H22*(1+Hypotheses!J83)) -> 0 | J22: =(I22*(1+Hypotheses!K83)) -> 0
C23: Total Chiffre d'affaires | E23: =Hypotheses!$E$13 -> XOF | F23: =+F8+F11+F14+F17+F20 -> 78475000 | G23: =+G8+G11+G14+G17+G20 -> 523501250 | H23: =+H8+H11+H14+H17+H20 -> 5.4523244e+08 | I23: =+I8+I11+I14+I17+I20 -> 5.6840706e+08 | J23: =+J8+J11+J14+J17+J20 -> 5.9317591e+08
C24: Coûts Directs | E24: =Hypotheses!$E$13 -> XOF | F24: =F25+F26 -> 24339600 | G24: =F24+(F24*Hypotheses!H85) -> 24339600 | H24: =G24+(G24*Hypotheses!I85) -> 24339600 | I24: =H24+(H24*Hypotheses!J85) -> 24339600 | J24: =I24+(I24*Hypotheses!K85) -> 24339600
D25: =+Hypotheses!D86 -> Salaires & traitements | E25: =Hypotheses!$E$13 -> XOF | F25: ='Estimation des autres charges'!H19 -> 24000000 | G25: =+F25+(F25*Hypotheses!H86) -> 24720000 | H25: =+G25+(G25*Hypotheses!I86) -> 25461600 | I25: =+H25+(H25*Hypotheses!J86) -> 26225448 | J25: =+I25+(I25*Hypotheses!K86) -> 27012211
D26: =Hypotheses!D87 -> Achat de matière et fourniture liée | E26: =Hypotheses!$E$13 -> XOF | F26: =SUM(F27:F31) -> 339600 | G26: =SUM(G27:G31) -> 340680 | H26: =SUM(H27:H31) -> 341792.4 | I26: =SUM(I27:I31) -> 342938.17 | J26: =SUM(J27:J31) -> 344118.32
D27: =Hypotheses!D88 -> Matière A | E27: =Hypotheses!$E$13 -> XOF | F27: =Hypotheses!$F$26*Hypotheses!L48 -> 36000 | G27: =F27*(1+Hypotheses!H88) -> 37080 | H27: =G27*(1+Hypotheses!I88) -> 38192.4 | I27: =H27*(1+Hypotheses!J88) -> 39338.172 | J27: =I27*(1+Hypotheses!K88) -> 40518.317
D28: =Hypotheses!D89 -> Matière B | E28: =Hypotheses!$E$13 -> XOF | F28: =Hypotheses!$F$26*Hypotheses!L49 -> 176400 | G28: =F28*(1+Hypotheses!H89) -> 176400 | H28: =G28*(1+Hypotheses!I89) -> 176400 | I28: =H28*(1+Hypotheses!J89) -> 176400 | J28: =I28*(1+Hypotheses!K89) -> 176400
D29: =Hypotheses!D90 -> Matière C | E29: =Hypotheses!$E$13 -> XOF | F29: =Hypotheses!$F$26*Hypotheses!L50 -> 55200 | G29: =F29*(1+Hypotheses!H90) -> 55200 | H29: =G29*(1+Hypotheses!I90) -> 55200 | I29: =H29*(1+Hypotheses!J90) -> 55200 | J29: =I29*(1+Hypotheses!K90) -> 55200
D30: =Hypotheses!D91 -> Matière D | E30: =Hypotheses!$E$13 -> XOF | F30: =Hypotheses!$F$26*Hypotheses!L51 -> 28800 | G30: =F30*(1+Hypotheses!H91) -> 28800 | H30: =G30*(1+Hypotheses!I91) -> 28800 | I30: =H30*(1+Hypotheses!J91) -> 28800 | J30: =I30*(1+Hypotheses!K91) -> 28800
D31: =Hypotheses!D92 -> Matière E | E31: =Hypotheses!$E$13 -> XOF | F31: =Hypotheses!$F$26*Hypotheses!L52 -> 43200 | G31: =F31*(1+Hypotheses!H92) -> 43200 | H31: =G31*(1+Hypotheses!I92) -> 43200 | I31: =H31*(1+Hypotheses!J92) -> 43200 | J31: =I31*(1+Hypotheses!K92) -> 43200
C32: Marge brute | E32: =Hypotheses!$E$13 -> XOF | F32: =F23-F24 -> 54135400 | G32: =G23-G24 -> 499161650 | H32: =H23-H24 -> 5.2089284e+08 | I32: =I23-I24 -> 5.4406746e+08 | J32: =J23-J24 -> 5.6883631e+08
D33: =Hypotheses!D93 -> Autres achats | E33: =Hypotheses!$E$13 -> XOF | F33: =SUM(F34:F42) -> 27000000 | G33: =SUM(G34:G42) -> 27420000 | H33: =SUM(H34:H42) -> 27847200 | I33: =SUM(I34:I42) -> 28281732 | J33: =SUM(J34:J42) -> 28723731
D34: =Hypotheses!D94 -> Eau | E34: =Hypotheses!$E$13 -> XOF | F34: ='Estimation des autres charges'!B40 -> 0 | G34: =+F34+(F34*Hypotheses!H94) -> 0 | H34: =+G34+(G34*Hypotheses!I94) -> 0 | I34: =+H34+(H34*Hypotheses!J94) -> 0 | J34: =+I34+(I34*Hypotheses!K94) -> 0
D35: =Hypotheses!D95 -> Electricité | E35: =Hypotheses!$E$13 -> XOF | F35: ='Estimation des autres charges'!B19 -> 0 | G35: =+F35+(F35*Hypotheses!H95) -> 0 | H35: =+G35+(G35*Hypotheses!I95) -> 0 | I35: =+H35+(H35*Hypotheses!J95) -> 0 | J35: =+I35+(I35*Hypotheses!K95) -> 0
D36: =Hypotheses!D96 -> Téléphone et internet | E36: =Hypotheses!$E$13 -> XOF | F36: ='Estimation des autres charges'!B60 -> 0 | G36: =+F36+(F36*Hypotheses!H96) -> 0 | H36: =+G36+(G36*Hypotheses!I96) -> 0 | I36: =+H36+(H36*Hypotheses!J96) -> 0 | J36: =+I36+(I36*Hypotheses!K96) -> 0
D37: =Hypotheses!D97 -> Fourniture de bureau | E37: =Hypotheses!$E$13 -> XOF | F37: 0 | G37: =+F37+(F37*Hypotheses!H97) -> 0 | H37: =+G37+(G37*Hypotheses!I97) -> 0 | I37: =+H37+(H37*Hypotheses!J97) -> 0 | J37: =+I37+(I37*Hypotheses!K97) -> 0
D38: =Hypotheses!D98 -> Entretien | E38: =Hypotheses!$E$13 -> XOF | F38: 0 | G38: =+F38+(F38*Hypotheses!H98) -> 0 | H38: =+G38+(G38*Hypotheses!I98) -> 0 | I38: =+H38+(H38*Hypotheses!J98) -> 0 | J38: =+I38+(I38*Hypotheses!K98) -> 0
D39: =Hypotheses!D99 -> Achat de prestation de service | E39: =Hypotheses!$E$13 -> XOF | F39: 15000000 | G39: =+F39+(F39*Hypotheses!H99) -> 15300000 | H39: =+G39+(G39*Hypotheses!I99) -> 15606000 | I39: =+H39+(H39*Hypotheses!J99) -> 15918120 | J39: =+I39+(I39*Hypotheses!K99) -> 16236482
D40: =Hypotheses!D100 -> Achat d'emballage | E40: =Hypotheses!$E$13 -> XOF | F40: 0 | G40: =+F40+(F40*Hypotheses!H100) -> 0 | H40: =+G40+(G40*Hypotheses!I100) -> 0 | I40: =+H40+(H40*Hypotheses!J100) -> 0 | J40: =+I40+(I40*Hypotheses!K100) -> 0
D41: =Hypotheses!D101 -> Carburant | E41: =Hypotheses!$E$13 -> XOF | F41: 12000000 | G41: =+F41+(F41*Hypotheses!H101) -> 12120000 | H41: =+G41+(G41*Hypotheses!I101) -> 12241200 | I41: =+H41+(H41*Hypotheses!J101) -> 12363612 | J41: =+I41+(I41*Hypotheses!K101) -> 12487248
D42: =Hypotheses!D102 -> Rabais, Remises et Ristourne | E42: =Hypotheses!$E$13 -> XOF | F42: 0 | G42: =+F42+(F42*Hypotheses!H102) -> 0 | H42: =+G42+(G42*Hypotheses!I102) -> 0 | I42: =+H42+(H42*Hypotheses!J102) -> 0 | J42: =+I42+(I42*Hypotheses!K102) -> 0
D43: =Hypotheses!D103 -> Transport | E43: =Hypotheses!$E$13 -> XOF | F43: 2900000 | G43: =+F43+(F43*Hypotheses!H103) -> 2987000 | H43: =+G43+(G43*Hypotheses!I103) -> 3076610 | I43: =+H43+(H43*Hypotheses!J103) -> 3168908.3 | J43: =+I43+(I43*Hypotheses!K103) -> 3263975.5
...

Sheet Amort_Immobilisation
C1: Investissements
C4: Aménagements | D4: Quantité | E4: Unité | F4: Prix Unitaire | G4: Prix Total
C5: travaux de construction et d'aménagement | D5: 1 | E5: u | F5: 0 | G5: =D5*F5 -> 0
C6: Carrelage | D6: 1 | E6: u | F6: 0
C7: Menuiserie | D7: 1 | E7: u | F7: 2300000 | G7: =D7*F7 -> 2300000
C8: Peinture | D8: 1 | E8: u | F8: 0
C9: Plomberie | D9: 1 | E9: u | F9: 0 | G9: =D9*F9 -> 0
C10: Visuel | D10: 1 | E10: u | F10: 0 | G10: =D10*F10 -> 0
C11: Electricité | D11: 1 | E11: u | F11: 0 | G11: =D11*F11 -> 0
C12: Total | G12: =SUM(G5:G11) -> 2300000
C14: Matériel de Production | D14: Quantité | E14: Unité | F14: Prix Unitaire | G14: Prix Total
D15: 1 | E15: u | F15: 0 | G15: =D15*F15 -> 0
D16: 1 | E16: u | F16: 0 | G16: =D16*F16 -> 0
D17: 1 | E17: u | F17: 0 | G17: =D17*F17 -> 0
D18: 1 | E18: u | F18: 0 | G18: =D18*F18 -> 0
D19: 1 | E19: u | F19: 0 | G19: =D19*F19 -> 0
D20: 1 | E20: u | F20: 0 | G20: =D20*F20 -> 0
C21: Total | G21: =SUM(G15:G20) -> 0
C24: Autres investissements | D24: Quantité | E24: Unité | F24: Prix Unitaire | G24: Prix Total
C25: Terrain | D25: 1 | E25: u | F25: 0 | G25: =D25*F25 -> 0
C26: Batiment | D26: 1 | E26: u | F26: 30000000 | G26: =D26*F26 -> 30000000
C27: Véhicule | D27: 1 | E27: u | F27: 5000000 | G27: =D27*F27 -> 5000000
C28: équipement solaire | D28: 1 | E28: u | F28: 0 | G28: =D28*F28 -> 0
C29: Matériel et Mobilier de bureau | D29: 1 | E29: u | F29: 0 | G29: =D29*F29 -> 0
C30: Total | G30: =SUM(G22:G29) -> 35000000
C34: Dotation aux amortissements
C38: DOTATION AUX AMORTISSEMENTS
C40: Rubrique | D40: Montant | E40: Taux | F40: Annuité | G40: =Hypotheses!G5 -> 2025 | H40: =Hypotheses!H5 -> 2026 | I40: =Hypotheses!I5 -> 2027 | J40: =Hypotheses!J5 -> 2028 | K40: =Hypotheses!K5 -> 2029
C42: Terrains | D42: =+G25 -> 0
C43: Batiments & travaux publics | D43: =+G26 -> 30000000 | E43: =1/Amort_MMB -> 0.1 | F43: =$D43*$E43 -> 3000000 | G43: =$D43*$E43 -> 3000000 | H43: =$D43*$E43 -> 3000000 | I43: =$D43*$E43 -> 3000000 | J43: =$D43*$E43 -> 3000000 | K43: =$D43*$E43 -> 3000000
C44: Aménagement, agencement et Installation | D44: =G12 -> 2300000 | E44: =1/Amort_Equipement -> 0.1 | F44: =$D44*$E44 -> 230000 | G44: =$D44*$E44 -> 230000 | H44: =$D44*$E44 -> 230000 | I44: =$D44*$E44 -> 230000 | J44: =$D44*$E44 -> 230000 | K44: =$D44*$E44 -> 230000
C45: Matériel d'exploitation | D45: =G21 -> 0 | E45: =1/Amort_Vehicule -> 0.1 | F45: =$D45*$E45 -> 0 | G45: =$D45*$E45 -> 0 | H45: =$D45*$E45 -> 0 | I45: =$D45*$E45 -> 0 | J45: =$D45*$E45 -> 0 | K45: =$D45*$E45 -> 0
C46: Véhicule | D46: =+G27 -> 5000000 | E46: =1/Amort_Installation -> 0.2 | F46: =$D46*$E46 -> 1000000 | G46: =$D46*$E46 -> 1000000 | H46: =$D46*$E46 -> 1000000 | I46: =$D46*$E46 -> 1000000 | J46: =$D46*$E46 -> 1000000 | K46: =$D46*$E46 -> 1000000
C47: Autres matériels et outillages | D47: =+G28 -> 0 | E47: =1/Hypotheses!F38 -> 0.2 | F47: =$D47*$E47 -> 0 | G47: =$D47*$E47 -> 0 | H47: =$D47*$E47 -> 0 | I47: =$D47*$E47 -> 0 | J47: =$D47*$E47 -> 0 | K47: =$D47*$E47 -> 0
C48: Matériel et Mobilier de bureau | D48: =+G29 -> 0 | E48: =1/Hypotheses!F39 -> 0.2 | F48: =$D48*$E48 -> 0 | G48: =$D48*$E48 -> 0 | H48: =$D48*$E48 -> 0 | I48: =$D48*$E48 -> 0 | J48: =$D48*$E48 -> 0 | K48: =$D48*$E48 -> 0
C49: Dotation aux amortissements | G49: =SUM(G42:G48) -> 4230000 | H49: =SUM(H42:H48) -> 4230000 | I49: =SUM(I42:I48) -> 4230000 | J49: =SUM(J42:J48) -> 4230000 | K49: =SUM(K42:K48) -> 4230000

Sheet TA _Invest
A2: montant | B2: =Amort_Immobilisation!G12+Amort_Immobilisation!G21+Amort_Immobilisation!G30 -> 37300000
A3: durée (mois) | B3: 60
A4: différé (mois) | B4: 0
A5: taux (%) | B5: =Hypotheses!F23 -> 9
A6: échéance | B6: =IF(B4=0,-PMT(B9,B3,B2),-PMT(B9,B3-B4,B2)) -> 802276.93
A7: assurance (%) | B7: 0
A8: tob (%) | B8: 17
A9: tx synthétique | B9: =((B5/100)*(1+B8/100)+B7/100)/12 -> 0.008775
A11: ech différé | B11: =IF(B4=0,0,(1+B8/100)*(B2*B5/100)/12) -> 0
A12: coût ct | B12: =+B6*B3 -> 48136616
A14: n° | C14: principal | D14: profit | E14: tob | F14: annuité | G14: restant dû
G15: =+B2 -> 37300000
A16: 1 | C16: =+F16-D16-E16 -> 474969.43 | D16: =+G15*$B$5/1200 -> 279750 | E16: =+D16*$B$8/100 -> 47557.5 | F16: =+$B$6 -> 802276.93 | G16: =+G15-C16 -> 36825031 | J16: =Hypotheses!G5 -> 2025 | K16: =Hypotheses!H5 -> 2026 | L16: =Hypotheses!I5 -> 2027 | M16: =Hypotheses!J5 -> 2028 | N16: =Hypotheses!K5 -> 2029
A17: 2 | C17: =+F17-D17-E17 -> 479137.28 | D17: =+G16*$B$5/1200 -> 276187.73 | E17: =+D17*$B$8/100 -> 46951.914 | F17: =+$B$6 -> 802276.93 | G17: =+G16-C17 -> 36345893 | I17: Remboursement en capital | J17: =SUM(C16:C27) -> 5982918.8 | K17: =SUM(C28:C39) -> 6644232.8 | L17: =SUM(C40:C51) -> 7378644.2 | M17: =SUM(C52:C63) -> 8194232.8 | N17: =SUM(C64:C75) -> 9099971.4
A18: 3 | C18: =+F18-D18-E18 -> 483341.71 | D18: =+G17*$B$5/1200 -> 272594.2 | E18: =+D18*$B$8/100 -> 46341.014 | F18: =+$B$6 -> 802276.93 | G18: =+G17-C18 -> 35862552 | I18: Intérêts + TOB | J18: =SUM(D16:D27)+SUM(E16:E27) -> 3644404.3 | K18: =SUM(D28:D39)+SUM(E28:E39) -> 2983090.3 | L18: =SUM(D40:D51)+SUM(E40:E51) -> 2248678.9 | M18: =SUM(D52:D63)+SUM(E52:E63) -> 1433090.3 | N18: =SUM(D64:D75)+SUM(E64:E75) -> 527351.71
A19: 4 | C19: =+F19-D19-E19 -> 487583.04 | D19: =+G18*$B$5/1200 -> 268969.14 | E19: =+D19*$B$8/100 -> 45724.753 | F19: =+$B$6 -> 802276.93 | G19: =+G18-C19 -> 35374969
A20: 5 | C20: =+F20-D20-E20 -> 491861.58 | D20: =+G19*$B$5/1200 -> 265312.26 | E20: =+D20*$B$8/100 -> 45103.085 | F20: =+$B$6 -> 802276.93 | G20: =+G19-C20 -> 34883107
A21: 6 | C21: =+F21-D21-E21 -> 496177.66 | D21: =+G20*$B$5/1200 -> 261623.3 | E21: =+D21*$B$8/100 -> 44475.961 | F21: =+$B$6 -> 802276.93 | G21: =+G20-C21 -> 34386929
A22: 7 | C22: =+F22-D22-E22 -> 500531.62 | D22: =+G21*$B$5/1200 -> 257901.97 | E22: =+D22*$B$8/100 -> 43843.335 | F22: =+$B$6 -> 802276.93 | G22: =+G21-C22 -> 33886398
A23: 8 | C23: =+F23-D23-E23 -> 504923.79 | D23: =+G22*$B$5/1200 -> 254147.98 | E23: =+D23*$B$8/100 -> 43205.157 | F23: =+$B$6 -> 802276.93 | G23: =+G22-C23 -> 33381474
A24: 9 | C24: =+F24-D24-E24 -> 509354.49 | D24: =+G23*$B$5/1200 -> 250361.05 | E24: =+D24*$B$8/100 -> 42561.379 | F24: =+$B$6 -> 802276.93 | G24: =+G23-C24 -> 32872119
A25: 10 | C25: =+F25-D25-E25 -> 513824.08 | D25: =+G24*$B$5/1200 -> 246540.9 | E25: =+D25*$B$8/100 -> 41911.952 | F25: =+$B$6 -> 802276.93 | G25: =+G24-C25 -> 32358295
A26: 11 | C26: =+F26-D26-E26 -> 518332.88 | D26: =+G25*$B$5/1200 -> 242687.21 | E26: =+D26*$B$8/100 -> 41256.827 | F26: =+$B$6 -> 802276.93 | G26: =+G25-C26 -> 31839962
A27: 12 | C27: =+F27-D27-E27 -> 522881.26 | D27: =+G26*$B$5/1200 -> 238799.72 | E27: =+D27*$B$8/100 -> 40595.952 | F27: =+$B$6 -> 802276.93 | G27: =+G26-C27 -> 31317081
A28: 13 | C28: =+F28-D28-E28 -> 527469.54 | D28: =+G27*$B$5/1200 -> 234878.11 | E28: =+D28*$B$8/100 -> 39929.279 | F28: =+$B$6 -> 802276.93 | G28: =+G27-C28 -> 30789612
A29: 14 | C29: =+F29-D29-E29 -> 532098.08 | D29: =+G28*$B$5/1200 -> 230922.09 | E29: =+D29*$B$8/100 -> 39256.755 | F29: =+$B$6 -> 802276.93 | G29: =+G28-C29 -> 30257514
A30: 15 | C30: =+F30-D30-E30 -> 536767.24 | D30: =+G29*$B$5/1200 -> 226931.35 | E30: =+D30*$B$8/100 -> 38578.33 | F30: =+$B$6 -> 802276.93 | G30: =+G29-C30 -> 29720746
... A62: 47 | C62: =+F62-D62-E62 -> 709911.07 | D62: =+G61*$B$5/1200 -> 78945.173 | E62: =+D62*$B$8/100 -> 13420.679 | F62: =+$B$6 -> 802276.93 | G62: =+G61-C62 -> 9816111.9
A63: =A62+1 -> 48 | C63: =+F63-D63-E63 -> 716140.54 | D63: =+G62*$B$5/1200 -> 73620.84 | E63: =+D63*$B$8/100 -> 12515.543 | F63: =+$B$6 -> 802276.93 | G63: =+G62-C63 -> 9099971.4
A64: =A63+1 -> 49 | C64: =+F64-D64-E64 -> 722424.68 | D64: =+G63*$B$5/1200 -> 68249.786 | E64: =+D64*$B$8/100 -> 11602.464 | F64: =+$B$6 -> 802276.93 | G64: =+G63-C64 -> 8377546.7
A65: =A64+1 -> 50 | C65: =+F65-D65-E65 -> 728763.95 | D65: =+G64*$B$5/1200 -> 62831.6 | E65: =+D65*$B$8/100 -> 10681.372 | F65: =+$B$6 -> 802276.93 | G65: =+G64-C65 -> 7648782.8
A66: =A65+1 -> 51 | C66: =+F66-D66-E66 -> 735158.86 | D66: =+G65*$B$5/1200 -> 57365.871 | E66: =+D66*$B$8/100 -> 9752.198 | F66: =+$B$6 -> 802276.93 | G66: =+G65-C66 -> 6913623.9
A67: =A66+1 -> 52 | C67: =+F67-D67-E67 -> 741609.88 | D67: =+G66*$B$5/1200 -> 51852.179 | E67: =+D67*$B$8/100 -> 8814.8705 | F67: =+$B$6 -> 802276.93 | G67: =+G66-C67 -> 6172014
A68: =A67+1 -> 53 | C68: =+F68-D68-E68 -> 748117.5 | D68: =+G67*$B$5/1200 -> 46290.105 | E68: =+D68*$B$8/100 -> 7869.3179 | F68: =+$B$6 -> 802276.93 | G68: =+G67-C68 -> 5423896.5
A69: =A68+1 -> 54 | C69: =+F69-D69-E69 -> 754682.23 | D69: =+G68*$B$5/1200 -> 40679.224 | E69: =+D69*$B$8/100 -> 6915.4681 | F69: =+$B$6 -> 802276.93 | G69: =+G68-C69 -> 4669214.3
A70: =A69+1 -> 55 | C70: =+F70-D70-E70 -> 761304.57 | D70: =+G69*$B$5/1200 -> 35019.107 | E70: =+D70*$B$8/100 -> 5953.2482 | F70: =+$B$6 -> 802276.93 | G70: =+G69-C70 -> 3907909.7
A71: =A70+1 -> 56 | C71: =+F71-D71-E71 -> 767985.02 | D71: =+G70*$B$5/1200 -> 29309.323 | E71: =+D71*$B$8/100 -> 4982.5849 | F71: =+$B$6 -> 802276.93 | G71: =+G70-C71 -> 3139924.7
A72: =A71+1 -> 57 | C72: =+F72-D72-E72 -> 774724.09 | D72: =+G71*$B$5/1200 -> 23549.435 | E72: =+D72*$B$8/100 -> 4003.404 | F72: =+$B$6 -> 802276.93 | G72: =+G71-C72 -> 2365200.6
A73: =A72+1 -> 58 | C73: =+F73-D73-E73 -> 781522.29 | D73: =+G72*$B$5/1200 -> 17739.005 | E73: =+D73*$B$8/100 -> 3015.6308 | F73: =+$B$6 -> 802276.93 | G73: =+G72-C73 -> 1583678.3
A74: =A73+1 -> 59 | C74: =+F74-D74-E74 -> 788380.15 | D74: =+G73*$B$5/1200 -> 11877.588 | E74: =+D74*$B$8/100 -> 2019.1899 | F74: =+$B$6 -> 802276.93 | G74: =+G73-C74 -> 795298.18
...

Sheet TA _Exploitation
A2: montant | B2: 2000000
A3: durée (mois) | B3: 24
A4: différé (mois) | B4: 0
A5: taux (%) | B5: =Hypotheses!F23 -> 9
A6: échéance | B6: =IF(B4=0,-PMT(B9,B3,B2),-PMT(B9,B3-B4,B2)) -> 92779.86
A7: assurance (%) | B7: 0
A8: tob (%) | B8: 17
A9: tx synthétique | B9: =((B5/100)*(1+B8/100)+B7/100)/12 -> 0.008775
A11: ech différé | B11: =IF(B4=0,0,(1+B8/100)*(B2*B5/100)/12) -> 0
A12: coût ct | B12: =+B6*B3 -> 2226716.7
A14: n° | C14: principal | D14: profit | E14: tob | F14: annuité | G14: restant dû
G15: =+B2 -> 2000000
A16: 1 | C16: =+F16-D16-E16 -> 75229.86 | D16: =+G15*$B$5/1200 -> 15000 | E16: =+D16*$B$8/100 -> 2550 | F16: =+$B$6 -> 92779.86 | G16: =+G15-C16 -> 1924770.1 | J16: =Hypotheses!G5 -> 2025 | K16: =Hypotheses!H5 -> 2026
A17: 2 | C17: =+F17-D17-E17 -> 75890.002 | D17: =+G16*$B$5/1200 -> 14435.776 | E17: =+D17*$B$8/100 -> 2454.0819 | F17: =+$B$6 -> 92779.86 | G17: =+G16-C17 -> 1848880.1 | I17: Remboursement en capital | J17: =SUM(C16:C27) -> 947627.62 | K17: =SUM(C28:C39) -> 1052372.4
A18: 3 | C18: =+F18-D18-E18 -> 76555.937 | D18: =+G17*$B$5/1200 -> 13866.601 | E18: =+D18*$B$8/100 -> 2357.3222 | F18: =+$B$6 -> 92779.86 | G18: =+G17-C18 -> 1772324.2 | I18: Intérêts + TOB | J18: =SUM(D16:D27)+SUM(E16:E27) -> 165730.7 | K18: =SUM(D28:D39)+SUM(E28:E39) -> 60985.947
A19: 4 | C19: =+F19-D19-E19 -> 77227.716 | D19: =+G18*$B$5/1200 -> 13292.431 | E19: =+D19*$B$8/100 -> 2259.7134 | F19: =+$B$6 -> 92779.86 | G19: =+G18-C19 -> 1695096.5
A20: 5 | C20: =+F20-D20-E20 -> 77905.389 | D20: =+G19*$B$5/1200 -> 12713.224 | E20: =+D20*$B$8/100 -> 2161.248 | F20: =+$B$6 -> 92779.86 | G20: =+G19-C20 -> 1617191.1
A21: 6 | C21: =+F21-D21-E21 -> 78589.009 | D21: =+G20*$B$5/1200 -> 12128.933 | E21: =+D21*$B$8/100 -> 2061.9186 | F21: =+$B$6 -> 92779.86 | G21: =+G20-C21 -> 1538602.1
A22: 7 | C22: =+F22-D22-E22 -> 79278.627 | D22: =+G21*$B$5/1200 -> 11539.516 | E22: =+D22*$B$8/100 -> 1961.7177 | F22: =+$B$6 -> 92779.86 | G22: =+G21-C22 -> 1459323.5
A23: 8 | C23: =+F23-D23-E23 -> 79974.297 | D23: =+G22*$B$5/1200 -> 10944.926 | E23: =+D23*$B$8/100 -> 1860.6374 | F23: =+$B$6 -> 92779.86 | G23: =+G22-C23 -> 1379349.2
A24: 9 | C24: =+F24-D24-E24 -> 80676.072 | D24: =+G23*$B$5/1200 -> 10345.119 | E24: =+D24*$B$8/100 -> 1758.6702 | F24: =+$B$6 -> 92779.86 | G24: =+G23-C24 -> 1298673.1
A25: 10 | C25: =+F25-D25-E25 -> 81384.004 | D25: =+G24*$B$5/1200 -> 9740.0482 | E25: =+D25*$B$8/100 -> 1655.8082 | F25: =+$B$6 -> 92779.86 | G25: =+G24-C25 -> 1217289.1
A26: 11 | C26: =+F26-D26-E26 -> 82098.149 | D26: =+G25*$B$5/1200 -> 9129.6682 | E26: =+D26*$B$8/100 -> 1552.0436 | F26: =+$B$6 -> 92779.86 | G26: =+G25-C26 -> 1135190.9
A27: 12 | C27: =+F27-D27-E27 -> 82818.56 | D27: =+G26*$B$5/1200 -> 8513.932 | E27: =+D27*$B$8/100 -> 1447.3684 | F27: =+$B$6 -> 92779.86 | G27: =+G26-C27 -> 1052372.4
A28: 13 | C28: =+F28-D28-E28 -> 83545.293 | D28: =+G27*$B$5/1200 -> 7892.7928 | E28: =+D28*$B$8/100 -> 1341.7748 | F28: =+$B$6 -> 92779.86 | G28: =+G27-C28 -> 968827.09
A29: 14 | C29: =+F29-D29-E29 -> 84278.403 | D29: =+G28*$B$5/1200 -> 7266.2031 | E29: =+D29*$B$8/100 -> 1235.2545 | F29: =+$B$6 -> 92779.86 | G29: =+G28-C29 -> 884548.68
A30: 15 | C30: =+F30-D30-E30 -> 85017.946 | D30: =+G29*$B$5/1200 -> 6634.1151 | E30: =+D30*$B$8/100 -> 1127.7996 | F30: =+$B$6 -> 92779.86 | G30: =+G29-C30 -> 799530.74
... A39: 24 | C39: =+F39-D39-E39 -> 91972.799 | D39: =+G38*$B$5/1200 -> 689.79599 | E39: =+D39*$B$8/100 -> 117.26532 | F39: =+$B$6 -> 92779.86 | G39: =+G38-C39 -> -3.6379788e-10
C41: =SUM(C16:C39) -> 2000000 | D41: =SUM(D16:D39) -> 193774.92 | E41: =SUM(E16:E39) -> 32941.736 | F41: =SUM(F16:F39) -> 2226716.7

Sheet Feuil1

Sheet CEP
C2: COMPTE D'EXPLOITATION PREVISIONNEL
D6: =OPEX!F5 -> 2025 | E6: =OPEX!G5 -> 2026 | F6: =OPEX!H5 -> 2027 | G6: =OPEX!I5 -> 2028 | H6: =OPEX!J5 -> 2029
C7: Rurbiques
C9: Chiffre d'affaires | D9: =OPEX!F23 -> 78475000 | E9: =OPEX!G23 -> 523501250 | F9: =OPEX!H23 -> 5.4523244e+08 | G9: =OPEX!I23 -> 5.6840706e+08 | H9: =OPEX!J23 -> 5.9317591e+08
C10: Salaires | D10: =OPEX!F25 -> 24000000 | E10: =OPEX!G25 -> 24720000 | F10: =OPEX!H25 -> 25461600 | G10: =OPEX!I25 -> 26225448 | H10: =OPEX!J25 -> 27012211
C11: Autres charges d'exploitation | D11: =OPEX!F26+OPEX!F33+OPEX!F43+OPEX!F44+OPEX!F45+OPEX!F46+OPEX!F47 -> 30239600 | E11: =OPEX!G26+OPEX!G33+OPEX!G43+OPEX!G44+OPEX!G45+OPEX!G46+OPEX!G47 -> 30747680 | F11: =OPEX!H26+OPEX!H33+OPEX!H43+OPEX!H44+OPEX!H45+OPEX!H46+OPEX!H47 -> 31265602 | G11: =OPEX!I26+OPEX!I33+OPEX!I43+OPEX!I44+OPEX!I45+OPEX!I46+OPEX!I47 -> 31793578 | H11: =OPEX!J26+OPEX!J33+OPEX!J43+OPEX!J44+OPEX!J45+OPEX!J46+OPEX!J47 -> 32331824
C12: Excédent brut d'exploitation | D12: =D9-D10-D11 -> 24235400 | E12: =E9-E10-E11 -> 468033570 | F12: =F9-F10-F11 -> 4.8850524e+08 | G12: =G9-G10-G11 -> 5.1038804e+08 | H12: =H9-H10-H11 -> 5.3383188e+08
C13: DAP | D13: =OPEX!F49 -> 4230000 | E13: =OPEX!G49 -> 4230000 | F13: =OPEX!H49 -> 4230000 | G13: =OPEX!I49 -> 4230000 | H13: =OPEX!J49 -> 4230000
C14: Résultat d'exploitation | D14: =D12-D13 -> 20005400 | E14: =E12-E13 -> 463803570 | F14: =F12-F13 -> 4.8427524e+08 | G14: =G12-G13 -> 5.0615804e+08 | H14: =H12-H13 -> 5.2960188e+08
C15: Charges d'intérêts | D15: =OPEX!F53 -> 6148649.5 | E15: =OPEX!G53 -> 6705218.7 | F15: =OPEX!H53 -> 7378644.2 | G15: =OPEX!I53 -> 8194232.8 | H15: =OPEX!J53 -> 9099971.4
C16: Résultat avant impôt | D16: =D14-D15 -> 13856750 | E16: =E14-E15 -> 4.5709835e+08 | F16: =F14-F15 -> 4.7689659e+08 | G16: =G14-G15 -> 4.979638e+08 | H16: =H14-H15 -> 5.2050191e+08
C17: IS | D17: =IF(D16<0,500000,IF(D16*Taux_IS<500000,500000,D16*Taux_IS)) -> 4157025.1 | E17: =IF(E16<0,500000,IF(E16*Taux_IS<500000,500000,E16*Taux_IS)) -> 1.3712951e+08 | F17: =IF(F16<0,500000,IF(F16*Taux_IS<500000,500000,F16*Taux_IS)) -> 1.4306898e+08 | G17: =IF(G16<0,500000,IF(G16*Taux_IS<500000,500000,G16*Taux_IS)) -> 1.4938914e+08 | H17: =IF(H16<0,500000,IF(H16*Taux_IS<500000,500000,H16*Taux_IS)) -> 1.5615057e+08
C18: Résultat net | D18: =D16-D17 -> 9699725.3 | E18: =E16-E17 -> 3.1996885e+08 | F18: =F16-F17 -> 3.3382761e+08 | G18: =G16-G17 -> 3.4857466e+08 | H18: =H16-H17 -> 3.6435133e+08
C23: COMPTE D'EXPLOITATION PREVISIONNEL STRESSE
C27: Stress Test | D27: =+Hypotheses!$F40 -> 0.85 | E27: =+Hypotheses!$F40 -> 0.85 | F27: =+Hypotheses!$F40 -> 0.85 | G27: =+Hypotheses!$F40 -> 0.85 | H27: =+Hypotheses!$F40 -> 0.85
C29: Année | D29: =D6 -> 2025 | E29: =E6 -> 2026 | F29: =F6 -> 2027 | G29: =G6 -> 2028 | H29: =H6 -> 2029
C30: Rurbiques
C32: Chiffre d'affaires | D32: =D27*D9 -> 66703750 | E32: =E27*E9 -> 4.4497606e+08 | F32: =F27*F9 -> 4.6344757e+08 | G32: =G27*G9 -> 4.83146e+08 | H32: =H27*H9 -> 5.0419953e+08
C33: Salaires | D33: =D10 -> 24000000 | E33: =E10 -> 24720000 | F33: =F10 -> 25461600 | G33: =G10 -> 26225448 | H33: =H10 -> 27012211
C34: Autres charges d'exploitation | D34: =D11 -> 30239600 | E34: =E11 -> 30747680 | F34: =F11 -> 31265602 | G34: =G11 -> 31793578 | H34: =H11 -> 32331824
C35: Excédent brut d'exploitation | D35: =D32-D33-D34 -> 12464150 | E35: =E32-E33-E34 -> 3.8950838e+08 | F35: =F32-F33-F34 -> 4.0672037e+08 | G35: =G32-G33-G34 -> 4.2512698e+08 | H35: =H32-H33-H34 -> 4.4485549e+08
C36: DAP | D36: =D13 -> 4230000 | E36: =E13 -> 4230000 | F36: =F13 -> 4230000 | G36: =G13 -> 4230000 | H36: =H13 -> 4230000
C37: Résultat d'exploitation | D37: =D35-D36 -> 8234150 | E37: =E35-E36 -> 3.8527838e+08 | F37: =F35-F36 -> 4.0249037e+08 | G37: =G35-G36 -> 4.2089698e+08 | H37: =H35-H36 -> 4.4062549e+08
C38: Charges d'intérêts | D38: =D15 -> 6148649.5 | E38: =E15 -> 6705218.7 | F38: =F15 -> 7378644.2 | G38: =G15 -> 8194232.8 | H38: =H15 -> 9099971.4
C39: Résultat avant impôt | D39: =D37-D38 -> 2085500.5 | E39: =E37-E38 -> 3.7857316e+08 | F39: =F37-F38 -> 3.9511173e+08 | G39: =G37-G38 -> 4.1270274e+08 | H39: =H37-H38 -> 4.3152552e+08
C40: IS | D40: =D17 -> 4157025.1 | E40: =E17 -> 1.3712951e+08 | F40: =F17 -> 1.4306898e+08 | G40: =G17 -> 1.4938914e+08 | H40: =H17 -> 1.5615057e+08
C41: Résultat net | D41: =D39-D40 -> -2071524.7 | E41: =E39-E40 -> 2.4144366e+08 | F41: =F39-F40 -> 2.5204275e+08 | G41: =G39-G40 -> 2.633136e+08 | H41: =H39-H40 -> 2.7537495e+08
D104: 2020 | E104: 2021 | F104: 2022 | G104: 2023 | H104: 2024
D105: 7800000 | E105: 8580000 | F105: 9438000 | G105: 9909900 | H105: 10405395
D106: 82075621 | E106: 89266621 | F106: 97176721 | G106: 101527276 | H106: 106095359
D107: 41016065 | E107: 43844765 | F107: 50727126 | G107: 55238883 | H107: 60034881
D120: #REF!
D122: #REF! | E122: - | F122: -
D123: #REF! | E123: #REF! | F123: -
D124: #REF! | E124: #REF! | F124: #REF!
D125: #REF! | E125: #REF! | F125: #REF!
D126: #REF! | E126: #REF! | F126: #REF!
D127: #REF! | E127: #REF! | F127: #REF!

Sheet Plan tréso
C2: Plan de trésorerie
F5: =OPEX!F5 -> 2025 | G5: =OPEX!G5 -> 2026 | H5: =OPEX!H5 -> 2027 | I5: =OPEX!I5 -> 2028 | J5: =OPEX!J5 -> 2029
C7: Solde début de période | G7: =F25 -> 13494719 | H7: =G25 -> 4.7078761e+08 | I7: =H25 -> 9.4966552e+08 | J7: =I25 -> 1.4504262e+09
C8: Recettes | E8: tot. Elev
D9: Encaissement | E9: =Hypotheses!$E$13 -> XOF
D10: Vente de services | F10: =OPEX!F23 -> 78475000 | G10: =OPEX!G23 -> 523501250 | H10: =OPEX!H23 -> 5.4523244e+08 | I10: =OPEX!I23 -> 5.6840706e+08 | J10: =OPEX!J23 -> 5.9317591e+08
D11: Emprunt | F11: ='TA _Invest'!B2+'TA _Exploitation'!B2 -> 39300000
C12: Total Chiffre d'affaires | D12: Encaissement | E12: =Hypotheses!$E$13 -> XOF | F12: =SUM(F10:F11)+F7 -> 117775000 | G12: =SUM(G10:G11)+G7 -> 5.3699597e+08 | H12: =SUM(H10:H11)+H7 -> 1.01602e+09 | I12: =SUM(I10:I11)+I7 -> 1.5180726e+09 | J12: =SUM(J10:J11)+J7 -> 2.0436021e+09
D13: Décaissement | E13: =Hypotheses!$E$13 -> XOF
D14: =OPEX!D25 -> Salaires & traitements | E14: =Hypotheses!$E$13 -> XOF | F14: =OPEX!F25 -> 24000000 | G14: =OPEX!G25 -> 24720000 | H14: =OPEX!H25 -> 25461600 | I14: =OPEX!I25 -> 26225448 | J14: =OPEX!J25 -> 27012211
D15: =OPEX!D26 -> Achat de matière et fourniture liée | E15: =Hypotheses!$E$13 -> XOF | F15: =OPEX!F26 -> 339600 | G15: =OPEX!G26 -> 340680 | H15: =OPEX!H26 -> 341792.4 | I15: =OPEX!I26 -> 342938.17 | J15: =OPEX!J26 -> 344118.32
D16: =OPEX!D33 -> Autres achats | E16: =Hypotheses!$E$13 -> XOF | F16: =OPEX!F33 -> 27000000 | G16: =OPEX!G33 -> 27420000 | H16: =OPEX!H33 -> 27847200 | I16: =OPEX!I33 -> 28281732 | J16: =OPEX!J33 -> 28723731
D17: =OPEX!D43 -> Transport | E17: =Hypotheses!$E$13 -> XOF | F17: =OPEX!F43 -> 2900000 | G17: =OPEX!G43 -> 2987000 | H17: =OPEX!H43 -> 3076610 | I17: =OPEX!I43 -> 3168908.3 | J17: =OPEX!J43 -> 3263975.5
D18: =OPEX!D44 -> Services Extérieurs | E18: =Hypotheses!$E$13 -> XOF | F18: =OPEX!F44 -> 0 | G18: =OPEX!G44 -> 0 | H18: =OPEX!H44 -> 0 | I18: =OPEX!I44 -> 0 | J18: =OPEX!J44 -> 0
D19: =OPEX!D45 -> Location | E19: =Hypotheses!$E$13 -> XOF | F19: =OPEX!F45 -> 0 | G19: =OPEX!G45 -> 0 | H19: =OPEX!H45 -> 0 | I19: =OPEX!I45 -> 0 | J19: =OPEX!J45 -> 0
D20: =OPEX!D46 -> Impôt et Taxes | E20: =Hypotheses!$E$13 -> XOF | F20: =OPEX!F46 -> 0 | G20: =OPEX!G46 -> 0 | H20: =OPEX!H46 -> 0 | I20: =OPEX!I46 -> 0 | J20: =OPEX!J46 -> 0
D21: =OPEX!D47 -> Autres charges | E21: =Hypotheses!$E$13 -> XOF | F21: =OPEX!F47 -> 0 | G21: =OPEX!G47 -> 0 | H21: =OPEX!H47 -> 0 | I21: =OPEX!I47 -> 0 | J21: =OPEX!J47 -> 0
D22: Investissement | E22: =Hypotheses!$E$13 -> XOF | F22: =Cashflow!F17 -> 39300000 | G22: =Cashflow!G17 -> 0 | H22: =Cashflow!H17 -> 0 | I22: =Cashflow!I17 -> 0 | J22: =Cashflow!J17 -> 0
D23: Remboursement emprunt+Intérêt | E23: =Hypotheses!$E$13 -> XOF | F23: ='TA _Invest'!J17+'TA _Invest'!J18+'TA _Exploitation'!J17+'TA _Exploitation'!J18 -> 10740681 | G23: ='TA _Invest'!K17+'TA _Invest'!K18+'TA _Exploitation'!K17+'TA _Exploitation'!K18 -> 10740681 | H23: ='TA _Invest'!L17+'TA _Invest'!L18+'TA _Exploitation'!L17+'TA _Exploitation'!L18 -> 9627323.1 | I23: ='TA _Invest'!M17+'TA _Invest'!M18+'TA _Exploitation'!M17+'TA _Exploitation'!M18 -> 9627323.1 | J23: ='TA _Invest'!N17+'TA _Invest'!N18+'TA _Exploitation'!N17+'TA _Exploitation'!N18 -> 9627323.1
C24: Total Décaissement | E24: =Hypotheses!$E$13 -> XOF | F24: =SUM(F14:F23) -> 1.0428028e+08 | G24: =SUM(G14:G16)+SUM(G17:G23) -> 66208361 | H24: =SUM(H14:H16)+SUM(H17:H23) -> 66354526 | I24: =SUM(I14:I16)+SUM(I17:I23) -> 67646350 | J24: =SUM(J14:J16)+SUM(J17:J23) -> 68971359
C25: Solde fin de période | E25: =Hypotheses!$E$13 -> XOF | F25: =F12-F24 -> 13494719 | G25: =G12-G24 -> 4.7078761e+08 | H25: =H12-H24 -> 9.4966552e+08 | I25: =I12-I24 -> 1.4504262e+09 | J25: =J12-J24 -> 1.9746308e+09

Sheet Cashflow
C2: Cash-flow
C5: En milliers | D5: Sommaire | E5: unité | F5: =Hypotheses!G5 -> 2025 | G5: =Hypotheses!H5 -> 2026 | H5: =Hypotheses!I5 -> 2027 | I5: =Hypotheses!J5 -> 2028 | J5: =Hypotheses!K5 -> 2029
C7: TOTAL RESSOURCES
D8: Résultat Net | E8: =Hypotheses!$E$13 -> XOF | F8: =OPEX!F56 -> 9699725.3 | G8: =OPEX!G56 -> 3.204736e+08 | H8: =OPEX!H56 -> 3.3485227e+08 | I8: =OPEX!I56 -> 3.5013481e+08 | J8: =OPEX!J56 -> 3.6646305e+08
D9: Dotation aux Amortissements | E9: =Hypotheses!$E$13 -> XOF | F9: =OPEX!G49 -> 4230000 | G9: =OPEX!H49 -> 4230000 | H9: =OPEX!I49 -> 4230000 | I9: =OPEX!J49 -> 4230000 | J9: =OPEX!K49 -> 0
D10: Capacité d'autofinancement | E10: =Hypotheses!$E$13 -> XOF | F10: =SUM(F8:F9) -> 13929725 | G10: =SUM(G8:G9) -> 3.247036e+08 | H10: =SUM(H8:H9) -> 3.3908227e+08 | I10: =SUM(I8:I9) -> 3.5436481e+08 | J10: =SUM(J8:J9) -> 3.6646305e+08
D11: Apport en capital | E11: =Hypotheses!$E$13 -> XOF | F11: =Amort_Immobilisation!D61 -> 0 | G11: 0 | H11: 0 | I11: 0 | J11: 0
D12: Emprunt | E12: =Hypotheses!$E$13 -> XOF | F12: ='TA _Invest'!B2+'TA _Exploitation'!B2 -> 39300000 | G12: 0 | H12: 0 | I12: 0 | J12: 0
D13: Fond de roulement | E13: =Hypotheses!$E$13 -> XOF
D14: TOTAL INFLOW | E14: =Hypotheses!$E$13 -> XOF | F14: =SUM(F10:F13) -> 53229725 | G14: =SUM(G10:G13) -> 3.247036e+08 | H14: =SUM(H10:H13) -> 3.3908227e+08 | I14: =SUM(I10:I13) -> 3.5436481e+08 | J14: =SUM(J10:J13) -> 3.6646305e+08
C16: Cycle de financement
D17: Investissement | E17: =Hypotheses!$E$13 -> XOF | F17: =F12+F11 -> 39300000
D18: Remboursement des emprunts (Service de la dette) | E18: =Hypotheses!$E$13 -> XOF | F18: ='Plan tréso'!F23 -> 10740681 | G18: ='Plan tréso'!G23 -> 10740681 | H18: ='Plan tréso'!H23 -> 9627323.1 | I18: ='Plan tréso'!I23 -> 9627323.1 | J18: ='Plan tréso'!J23 -> 9627323.1
D19: Dotation Fonds de roulement | E19: =Hypotheses!$E$13 -> XOF
D20: TOTAL OUTFLOW | E20: =Hypotheses!$E$13 -> XOF | F20: =SUM(F17:F19) -> 50040681 | G20: =SUM(G17:G19) -> 10740681 | H20: =SUM(H17:H19) -> 9627323.1 | I20: =SUM(I17:I19) -> 9627323.1 | J20: =SUM(J17:J19) -> 9627323.1
C22: CASHFLOW NET | E22: =Hypotheses!$E$13 -> XOF | F22: =F14-F20 -> 3189043.9 | G22: =G14-G20 -> 3.1396292e+08 | H22: =H14-H20 -> 3.2945495e+08 | I22: =I14-I20 -> 3.4473749e+08 | J22: =J14-J20 -> 3.5683572e+08
C23: Solde treso d'ouverture | E23: =Hypotheses!$E$13 -> XOF | G23: =F24 -> 3189043.9 | H23: =G24 -> 3.1715196e+08 | I23: =H24 -> 6.4660691e+08 | J23: =I24 -> 9.913444e+08
C24: Solde tréso de cloture | E24: =Hypotheses!$E$13 -> XOF | F24: =F23+F22 -> 3189043.9 | G24: =G23+G22 -> 3.1715196e+08 | H24: =H23+H22 -> 6.4660691e+08 | I24: =I23+I22 -> 9.913444e+08 | J24: =J23+J22 -> 1.3481801e+09
D28: Fonds de roulement (planning)
D30: Délais clients | E30: FCFA | F30: =OPEX!F23*Delais_clients/jours_an -> 6450000 | G30: =OPEX!G23*Delais_clients/jours_an -> 43027500 | H30: =OPEX!H23*Delais_clients/jours_an -> 44813625 | I30: =OPEX!I23*Delais_clients/jours_an -> 46718389 | J30: =OPEX!J23*Delais_clients/jours_an -> 48754185
D31: Rotation des stocks | E31: FCFA | F31: =+OPEX!F26*Delais_Stocks/jours_an -> 55824.658 | G31: =+OPEX!G26*Delais_Stocks/jours_an -> 56002.192 | H31: =+OPEX!H26*Delais_Stocks/jours_an -> 56185.052 | I31: =+OPEX!I26*Delais_Stocks/jours_an -> 56373.398 | J31: =+OPEX!J26*Delais_Stocks/jours_an -> 56567.395
D32: Délais fournisseurs | E32: FCFA | F32: =+(OPEX!F26+OPEX!F33+OPEX!F43+OPEX!F44+OPEX!F45+OPEX!F46+OPEX!F47)*Delais_Frs/jours_an -> 2485446.6 | G32: =+(OPEX!G26+OPEX!G33+OPEX!G43+OPEX!G44+OPEX!G45+OPEX!G46+OPEX!G47)*Delais_Frs/jours_an -> 2527206.6 | H32: =+(OPEX!H26+OPEX!H33+OPEX!H43+OPEX!H44+OPEX!H45+OPEX!H46+OPEX!H47)*Delais_Frs/jours_an -> 2569775.5 | I32: =+(OPEX!I26+OPEX!I33+OPEX!I43+OPEX!I44+OPEX!I45+OPEX!I46+OPEX!I47)*Delais_Frs/jours_an -> 2613170.8 | J32: =+(OPEX!J26+OPEX!J33+OPEX!J43+OPEX!J44+OPEX!J45+OPEX!J46+OPEX!J47)*Delais_Frs/jours_an -> 2657410.2
D33: Besoin en fonds de roulement | E33: FCFA | F33: =SUM(F30:F31)-F32 -> 4020378.1 | G33: =SUM(G30:G31)-G32 -> 40556296 | H33: =SUM(H30:H31)-H32 -> 42300035 | I33: =SUM(I30:I31)-I32 -> 44161591 | J33: =SUM(J30:J31)-J32 -> 46153342
D34: Variation du Besoin en fonds de roulement | F34: =F33-E34 -> 4020378.1 | G34: =G33-F33 -> 36535918 | H34: =H33-G33 -> 1743738.9 | I34: =I33-H33 -> 1861556.8 | J34: =J33-I33 -> 1991750.5
E94: Year 0 | F94: =F5 -> 2025 | G94: =G5 -> 2026 | H94: =H5 -> 2027 | I94: =I5 -> 2028 | J94: =J5 -> 2029
D95: Cash flow | E95: -3.0009625e+10 | F95: =F22 -> 3189043.9 | G95: =G22 -> 3.1396292e+08 | H95: =H22 -> 3.2945495e+08 | I95: =I22 -> 3.4473749e+08 | J95: =J22 -> 3.5683572e+08

Sheet Données_Graph
A3: Analyse de la performance | H3: CROISSANCE
B4: Année | I4: Année
B5: 2020 | C5: 2021 | D5: 2022 | E5: 2023 | F5: 2024 | I5: 2020 | J5: 2021 | K5: 2022 | L5: 2023 | M5: 2024
A6: Chiffre d'affaire | B6: =OPEX!F23 -> 78475000 | C6: =OPEX!G23 -> 523501250 | D6: =OPEX!H23 -> 5.4523244e+08 | E6: =OPEX!I23 -> 5.6840706e+08 | F6: =OPEX!J23 -> 5.9317591e+08 | G6: =#REF! -> #REF! | H6: CA | I6: 0 | J6: =+(C6-B6)/B6 -> 5.6709302 | K6: =+(D6-C6)/C6 -> 0.041511243 | L6: =+(E6-D6)/D6 -> 0.042504121 | M6: =+(F6-E6)/E6 -> 0.043575902
A7: Exédent Brut d'exploitation | B7: =+OPEX!F52 -> 20005400 | C7: =+OPEX!G52 -> 464524650 | D7: =+OPEX!H52 -> 4.8573903e+08 | E7: =+OPEX!I52 -> 5.0838682e+08 | F7: =+OPEX!J52 -> 5.3261861e+08 | H7: EBE | I7: 0 | J7: =+(C7-B7)/B7 -> 22.219963 | K7: =+(D7-C7)/C7 -> 0.045669003 | L7: =+(E7-D7)/D7 -> 0.046625439 | M7: =+(F7-E7)/E7 -> 0.047664069
A8: Résultat d'exploitation | B8: =+OPEX!F54 -> 13856750 | C8: =+OPEX!G54 -> 4.5781943e+08 | D8: =+OPEX!H54 -> 4.7836038e+08 | E8: =+OPEX!I54 -> 5.0019259e+08 | F8: =+OPEX!J54 -> 5.2351864e+08 | H8: REX | I8: 0 | J8: =+(C8-B8)/B8 -> 32.039451 | K8: =+(D8-C8)/C8 -> 0.044866929 | L8: =+(E8-D8)/D8 -> 0.045639663 | M8: =+(F8-E8)/E8 -> 0.046634129
A9: Résultat net | B9: =+OPEX!F56 -> 9699725.3 | C9: =+OPEX!G56 -> 3.204736e+08 | D9: =+OPEX!H56 -> 3.3485227e+08 | E9: =+OPEX!I56 -> 3.5013481e+08 | F9: =+OPEX!J56 -> 3.6646305e+08 | H9: RN | I9: 0 | J9: =+(C9-B9)/B9 -> 32.039451 | K9: =+(D9-C9)/C9 -> 0.044866929 | L9: =+(E9-D9)/D9 -> 0.045639663 | M9: =+(F9-E9)/E9 -> 0.046634129
B12: Année
B13: 2020 | C13: 2021 | D13: 2022 | E13: 2023 | F13: 2024
A14: Nombre d'éléve | B14: =OPEX!F7 -> 15 | C14: =OPEX!G7 -> 136.15 | D14: =OPEX!H7 -> 141.2325 | E14: =OPEX!I7 -> 146.60178 | F14: =OPEX!J7 -> 152.28503
A17: Analyse Cash flow
A18: Année | B18: Année
B19: 2020 | C19: 2021 | D19: 2022 | E19: 2023 | F19: 2024
A20: CAF | B20: =Cashflow!F10 -> 13929725 | C20: =Cashflow!G10 -> 3.247036e+08 | D20: =Cashflow!H10 -> 3.3908227e+08 | E20: =Cashflow!I10 -> 3.5436481e+08 | F20: =Cashflow!J10 -> 3.6646305e+08
A21: Cashflow IN | B21: =Cashflow!F14 -> 53229725 | C21: =Cashflow!G14 -> 3.247036e+08 | D21: =Cashflow!H14 -> 3.3908227e+08 | E21: =Cashflow!I14 -> 3.5436481e+08 | F21: =Cashflow!J14 -> 3.6646305e+08
A22: Cashflow OUT | B22: =Cashflow!F20 -> 50040681 | C22: =Cashflow!G20 -> 10740681 | D22: =Cashflow!H20 -> 9627323.1 | E22: =Cashflow!I20 -> 9627323.1 | F22: =Cashflow!J20 -> 9627323.1
A23: Cashflow Net | B23: =Cashflow!F22 -> 3189043.9 | C23: =Cashflow!G22 -> 3.1396292e+08 | D23: =Cashflow!H22 -> 3.2945495e+08 | E23: =Cashflow!I22 -> 3.4473749e+08 | F23: =Cashflow!J22 -> 3.5683572e+08
A24: Trésorerie Net | B24: =Cashflow!F24 -> 3189043.9 | C24: =Cashflow!G24 -> 3.1715196e+08 | D24: =Cashflow!H24 -> 6.4660691e+08 | E24: =Cashflow!I24 -> 9.913444e+08 | F24: =Cashflow!J24 -> 1.3481801e+09

Sheet GRAPH

Sheet Equilibre
C1: Rentabilité financière
G2: =CEP!D6 -> 2025 | H2: =CEP!E6 -> 2026 | I2: =CEP!F6 -> 2027 | J2: =CEP!G6 -> 2028 | K2: =CEP!H6 -> 2029
F3: unité | G3: ="Année"&" "&G2 -> Année 2025 | H3: ="Année"&" "&H2 -> Année 2026 | I3: ="Année"&" "&I2 -> Année 2027 | J3: ="Année"&" "&J2 -> Année 2028 | K3: ="Année"&" "&K2 -> Année 2029
D6: + EBE (>0) | F6: FCFA | G6: =IF(CEP!D12>0,CEP!D12,0) -> 24235400 | H6: =IF(CEP!E12>0,CEP!E12,0) -> 468033570 | I6: =IF(CEP!F12>0,CEP!F12,0) -> 4.8850524e+08 | J6: =IF(CEP!G12>0,CEP!G12,0) -> 5.1038804e+08 | K6: =IF(CEP!H12>0,CEP!H12,0) -> 5.3383188e+08
D7: -Variation du BFE | F7: FCFA | G7: =+-Cashflow!F34 -> -4020378.1 | H7: =+-Cashflow!G34 -> -36535918 | I7: =+-Cashflow!H34 -> -1743738.9 | J7: =+-Cashflow!I34 -> -1861556.8 | K7: =+-Cashflow!J34 -> -1991750.5
D8: - Investissements | F8: FCFA | G8: =-(Amort_Immobilisation!G12+Amort_Immobilisation!G21+Amort_Immobilisation!G30) -> -37300000 | H8: 0 | I8: 0 | J8: 0 | K8: 0
D9: - EBE (<0) | F9: FCFA | G9: =+IF(CEP!D12<0,CEP!D12,0) -> 0 | H9: =+IF(CEP!E12<0,CEP!E12,0) -> 0 | I9: =+IF(CEP!F12<0,CEP!F12,0) -> 0 | J9: =+IF(CEP!G12<0,CEP!G12,0) -> 0 | K9: =+IF(CEP!H12<0,CEP!H12,0) -> 0
D10: = Flux projet (Cash Flows) | G10: =SUM(G6:G9) -> -17084978 | H10: =SUM(H6:H9) -> 4.3149765e+08 | I10: =SUM(I6:I9) -> 4.867615e+08 | J10: =SUM(J6:J9) -> 5.0852648e+08 | K10: =SUM(K6:K9) -> 5.3184013e+08
D11: Résultat avant impôt | G11: =CEP!D16 -> 13856750 | H11: =CEP!E16 -> 4.5709835e+08 | I11: =CEP!F16 -> 4.7689659e+08 | J11: =CEP!G16 -> 4.979638e+08 | K11: =CEP!H16 -> 5.2050191e+08
D13: TRI projet avant impôts | F13: =IRR(G10:K10) -> 25.380424
D16: - Impôts sur les bénéfices | F16: FCFA | G16: =-CEP!D17 -> -4157025.1 | H16: =-CEP!E17 -> -1.3712951e+08 | I16: =-CEP!F17 -> -1.4306898e+08 | J16: =-CEP!G17 -> -1.4938914e+08 | K16: =-CEP!H17 -> -1.5615057e+08
D17: = Flux projet | G17: =G10+G16 -> -21242003 | H17: =H10+H16 -> 2.9436815e+08 | I17: =I10+I16 -> 3.4369252e+08 | J17: =J10+J16 -> 3.5913734e+08 | K17: =K10+K16 -> 3.7568956e+08
D19: TRI projet après impôts | F19: =IRR(G17:K17) -> 14.015581
D22: Valeur actuelle nette | F22: {=NPV(F51,G10,H10:K10)} -> 3.5132771e+09
D25: Délais de Récupération du Capital investi
D26: Flux monétaires cumulés | G26: =G10 -> -17084978 | H26: =G26+H10 -> 4.1441267e+08 | I26: =H26+I10 -> 9.0117417e+08 | J26: =I26+J10 -> 1.4097007e+09 | K26: =J26+K10 -> 1.9415408e+09
D27: DRCI | E27: années | F27: =MATCH(0,G26:K26,1) -> 1
D29: Indice de profitabilité | F29: =F22/-G17+1 -> 166.39293
D32: Ratios annuels de couverture de la dette
D33: Trésorerie disponible avant service de la dette commerciale | G33: =G6+G7 -> 20215022 | H33: =H6+H7 -> 4.3149765e+08 | I33: =I6+I7 -> 4.867615e+08 | J33: =J6+J7 -> 5.0852648e+08 | K33: =K6+K7 -> 5.3184013e+08
D34: Intérêts | G34: ='TA _Invest'!J18+'TA _Exploitation'!J18 -> 3810135 | H34: ='TA _Invest'!K18+'TA _Exploitation'!K18 -> 3044076.3 | I34: ='TA _Invest'!L18+'TA _Exploitation'!L18 -> 2248678.9 | J34: ='TA _Invest'!M18+'TA _Exploitation'!M18 -> 1433090.3 | K34: ='TA _Invest'!N18+'TA _Exploitation'!N18 -> 527351.71
D35: Amortissement du principal | G35: ='TA _Invest'!J17+'TA _Exploitation'!J17 -> 6930546.4 | H35: ='TA _Invest'!K17+'TA _Exploitation'!K17 -> 7696605.2 | I35: ='TA _Invest'!L17+'TA _Exploitation'!L17 -> 7378644.2 | J35: ='TA _Invest'!M17+'TA _Exploitation'!M17 -> 8194232.8 | K35: ='TA _Invest'!N17+'TA _Exploitation'!N17 -> 9099971.4
D36: Service de la dette commerciale | G36: =SUM(G34:G35) -> 10740681 | H36: =SUM(H34:H35) -> 10740681 | I36: =SUM(I34:I35) -> 9627323.1 | J36: =SUM(J34:J35) -> 9627323.1 | K36: =SUM(K34:K35) -> 9627323.1
G38: =IF((G36>0),G33/G36," ") -> 1.8820986 | H38: =IF((H36>0),H33/H36," ") -> 40.174141 | I38: =IF((I36>0),I33/I36," ") -> 50.56042 | J38: =IF((J36>0),J33/J36," ") -> 52.821171 | K38: =IF((K36>0),K33/K36," ") -> 55.242784
D39: DSCR annuel | F39: =AVERAGE(H38:K38) -> 49.699629
D41: DSCR annuel minimum | F41: =MIN(H38:K38) -> 40.174141
D44: Ratios acturariels de couverture de la dette
D45: + Tirage dette | G45: ='TA _Invest'!B2+'TA _Exploitation'!B2 -> 39300000 | H45: 0 | I45: 0 | J45: 0 | K45: 0
D46: =" - "&D34 -> - Intérêts | G46: =-('TA _Invest'!J18)-('TA _Exploitation'!J18) -> -3810135 | H46: =-('TA _Invest'!K18)-('TA _Exploitation'!K18) -> -3044076.3 | I46: =-('TA _Invest'!L18)-('TA _Exploitation'!L18) -> -2248678.9 | J46: =-('TA _Invest'!M18)-('TA _Exploitation'!M18) -> -1433090.3 | K46: =-('TA _Invest'!N18)-('TA _Exploitation'!N18) -> -527351.71
D47: =" - "&D35 -> - Amortissement du principal | G47: =-('TA _Invest'!J17)-('TA _Exploitation'!J17) -> -6930546.4 | H47: =-('TA _Invest'!K17)-('TA _Exploitation'!K17) -> -7696605.2 | I47: =-('TA _Invest'!L17)-('TA _Exploitation'!L17) -> -7378644.2 | J47: =-('TA _Invest'!M17)-('TA _Exploitation'!M17) -> -8194232.8 | K47: =-('TA _Invest'!N17)-('TA _Exploitation'!N17) -> -9099971.4
D48: Solde des flux financiers dette commerciale | G48: =SUM(G45:G47) -> 28559319 | H48: =SUM(H45:H47) -> -10740681 | I48: =SUM(I45:I47) -> -9627323.1 | J48: =SUM(J45:J47) -> -9627323.1 | K48: =SUM(K45:K47) -> -9627323.1
D51: Taux actuariel annuel de la dette commerciale | F51: =-(IRR(G48:K48)) -> -0.14813867
D53: LLCR | F53: {=NPV(F51,G33:K33)/NPV(F51,G36:K36)} -> 42.997433
